Workbook
Name БазаВосток: #REF!
Name БазаЗапад: Запад!$A$2:$J$31
Name БазаСевер: #REF!
Name БазаЮг: Юг!$A$2:$J$31

Sheet Юг
A1: Продукт | B1: Цена | C1: Кол-во прод в кг | D1: Кол-во ост. | E1: Стоимость | F1: Поставщик | G1: Дата поставки | H1: План. Дата поставки | I1: Дата продажи | J1: Сост. Доставки
A2: Абрикосы | B2: 170 | C2: 20 | D2: =INT(0.25*C2) -> 5 | E2: =B2*C2 -> 3400 | F2: "ChinaKO TM" | G2: 46073 | H2: 46072 | I2: 46072 | J2: =IF(G2=H2,"Дост. в срок","Просрочена") -> Просрочена
A3: Груши | B3: 123 | C3: 12 | D3: =INT(0.25*C3) -> 3 | E3: =B3*C3 -> 1476 | F3: "ChinaKO TM" | G3: 46073 | H3: 46072 | I3: 46075 | J3: =IF(G3=H3,"Дост. в срок","Просрочена") -> Просрочена
A4: Персики | B4: 100 | C4: 18 | D4: =INT(0.25*C4) -> 4 | E4: =B4*C4 -> 1800 | F4: "ChinaKO TM" | G4: 46073 | H4: 46072 | I4: 46072 | J4: =IF(G4=H4,"Дост. в срок","Просрочена") -> Просрочена
A5: Черешня | B5: 190 | C5: 12 | D5: =INT(0.25*C5) -> 3 | E5: =B5*C5 -> 2280 | F5: "ChinaKO TM" | G5: 46073 | H5: 46072 | I5: 46072 | J5: =IF(G5=H5,"Дост. в срок","Просрочена") -> Просрочена
A6: Яблоки | B6: 78 | C6: 35 | D6: =INT(0.25*C6) -> 8 | E6: =B6*C6 -> 2730 | F6: "ChinaKO TM" | G6: 46073 | H6: 46072 | I6: 46072 | J6: =IF(G6=H6,"Дост. в срок","Просрочена") -> Просрочена
A7: Авокадо | B7: 260 | C7: 13 | D7: =INT(0.25*C7) -> 3 | E7: =B7*C7 -> 3380 | F7: "Japfruit ComLTD" | G7: 46071 | H7: 46071 | I7: 46076 | J7: =IF(G7=H7,"Дост. в срок","Просрочена") -> Дост. в срок
A8: Батат | B8: 142 | C8: 17 | D8: =INT(0.25*C8) -> 4 | E8: =B8*C8 -> 2414 | F8: "Japfruit ComLTD" | G8: 46071 | H8: 46071 | I8: 46072 | J8: =IF(G8=H8,"Дост. в срок","Просрочена") -> Дост. в срок
A9: Дайкон | B9: 130 | C9: 12 | D9: =INT(0.25*C9) -> 3 | E9: =B9*C9 -> 1560 | F9: "Japfruit ComLTD" | G9: 46071 | H9: 46071 | I9: 46072 | J9: =IF(G9=H9,"Дост. в срок","Просрочена") -> Дост. в срок
A10: Кольраби | B10: 163 | C10: 8 | D10: =INT(0.25*C10) -> 2 | E10: =B10*C10 -> 1304 | F10: "Japfruit ComLTD" | G10: 46071 | H10: 46071 | I10: 46072 | J10: =IF(G10=H10,"Дост. в срок","Просрочена") -> Дост. в срок
A11: Сельдерей | B11: 120 | C11: 2 | D11: =INT(0.25*C11) -> 0 | E11: =B11*C11 -> 240 | F11: "Japfruit ComLTD" | G11: 46071 | H11: 46071 | I11: 46075 | J11: =IF(G11=H11,"Дост. в срок","Просрочена") -> Дост. в срок
A12: Спаржа | B12: 163 | C12: 5 | D12: =INT(0.25*C12) -> 1 | E12: =B12*C12 -> 815 | F12: "Japfruit ComLTD" | G12: 46071 | H12: 46071 | I12: 46077 | J12: =IF(G12=H12,"Дост. в срок","Просрочена") -> Дост. в срок
A13: Топинамбур | B13: 105 | C13: 13 | D13: =INT(0.25*C13) -> 3 | E13: =B13*C13 -> 1365 | F13: "Japfruit ComLTD" | G13: 46071 | H13: 46071 | I13: 46076 | J13: =IF(G13=H13,"Дост. в срок","Просрочена") -> Дост. в срок
... A31: Чеснок | B31: 42 | C31: 30 | D31: =INT(0.25*C31) -> 7 | E31: =B31*C31 -> 1260 | F31: <<ООО>>"Зарница" | G31: 46070 | H31: 46070 | I31: 46077 | J31: =IF(G31=H31,"Дост. в срок","Просрочена") -> Дост. в срок

Sheet Север
A1: Продукт | B1: Цена | C1: Кол-во прод в кг | D1: Кол-во ост. | E1: Стоимость | F1: Поставщик | G1: Дата поставки | H1: План. Дата поставки | I1: Дата продажи | J1: Сост. Доставки
A2: Абрикосы | B2: 170 | C2: 20 | D2: =INT(0.25*C2) -> 5 | E2: =B2*C2 -> 3400 | F2: "ChinaKO TM" | G2: 46073 | H2: 46072 | I2: 46072 | J2: =IF(G2=H2,"Дост. в срок","Просрочена") -> Просрочена
A3: Авокадо | B3: 270 | C3: 15 | D3: =INT(0.25*C3) -> 3 | E3: =B3*C3 -> 4050 | F3: "Japfruit ComLTD" | G3: 46071 | H3: 46071 | I3: 46076 | J3: =IF(G3=H3,"Дост. в срок","Просрочена") -> Дост. в срок
A4: Баклажан | B4: 110 | C4: 18 | D4: =INT(0.25*C4) -> 4 | E4: =B4*C4 -> 1980 | F4: <<ООО>>"Зарница" | G4: 46070 | H4: 46070 | I4: 46075 | J4: =IF(G4=H4,"Дост. в срок","Просрочена") -> Дост. в срок
A5: Батат | B5: 150 | C5: 24 | D5: =INT(0.25*C5) -> 6 | E5: =B5*C5 -> 3600 | F5: "Japfruit ComLTD" | G5: 46071 | H5: 46071 | I5: 46072 | J5: =IF(G5=H5,"Дост. в срок","Просрочена") -> Дост. в срок
A6: Брокколи | B6: 170 | C6: 10 | D6: =INT(0.25*C6) -> 2 | E6: =B6*C6 -> 1700 | F6: <<ООО>>"Зарница" | G6: 46070 | H6: 46070 | I6: 46072 | J6: =IF(G6=H6,"Дост. в срок","Просрочена") -> Дост. в срок
A7: Брюква | B7: 113 | C7: 16 | D7: =INT(0.25*C7) -> 4 | E7: =B7*C7 -> 1808 | F7: <<ООО>>"Зарница" | G7: 46070 | H7: 46070 | I7: 46072 | J7: =IF(G7=H7,"Дост. в срок","Просрочена") -> Дост. в срок
A8: Горох | B8: 120 | C8: 15 | D8: =INT(0.25*C8) -> 3 | E8: =B8*C8 -> 1800 | F8: <<ООО>>"Зарница" | G8: 46070 | H8: 46070 | I8: 46075 | J8: =IF(G8=H8,"Дост. в срок","Просрочена") -> Дост. в срок
A9: Груши | B9: 150 | C9: 20 | D9: =INT(0.25*C9) -> 5 | E9: =B9*C9 -> 3000 | F9: "ChinaKO TM" | G9: 46073 | H9: 46072 | I9: 46075 | J9: =IF(G9=H9,"Дост. в срок","Просрочена") -> Просрочена
A10: Дайкон | B10: 130 | C10: 10 | D10: =INT(0.25*C10) -> 2 | E10: =B10*C10 -> 1300 | F10: "Japfruit ComLTD" | G10: 46071 | H10: 46071 | I10: 46072 | J10: =IF(G10=H10,"Дост. в срок","Просрочена") -> Дост. в срок
A11: Капуста | B11: 90 | C11: 18 | D11: =INT(0.25*C11) -> 4 | E11: =B11*C11 -> 1620 | F11: <<ООО>>"Зарница" | G11: 46070 | H11: 46070 | I11: 46076 | J11: =IF(G11=H11,"Дост. в срок","Просрочена") -> Дост. в срок
A12: Картофель | B12: 60 | C12: 200 | D12: =INT(0.25*C12) -> 50 | E12: =B12*C12 -> 12000 | F12: <<ООО>>"Зарница" | G12: 46070 | H12: 46070 | I12: 46076 | J12: =IF(G12=H12,"Дост. в срок","Просрочена") -> Дост. в срок
A13: Кольраби | B13: 190 | C13: 19 | D13: =INT(0.25*C13) -> 4 | E13: =B13*C13 -> 3610 | F13: "Japfruit ComLTD" | G13: 46071 | H13: 46071 | I13: 46072 | J13: =IF(G13=H13,"Дост. в срок","Просрочена") -> Дост. в срок
... A31: Яблоки | B31: 1000 | C31: 350 | D31: =INT(0.25*C31) -> 87 | E31: =B31*C31 -> 350000 | F31: "ChinaKO TM" | G31: 46073 | H31: 46072 | I31: 46072 | J31: =IF(G31=H31,"Дост. в срок","Просрочена") -> Просрочена

Sheet Запад
A1: Продукт | B1: Цена | C1: Кол-во прод в кг | D1: Кол-во ост. | E1: Стоимость | F1: Поставщик | G1: Дата поставки | H1: План. Дата поставки | I1: Дата продажи | J1: Сост. Доставки
A2: Абрикосы | B2: 180 | C2: 20 | D2: =INT(0.25*C2) -> 5 | E2: =B2*C2 -> 3600 | F2: "ChinaKO TM" | G2: 46073 | H2: 46071 | I2: 46076 | J2: =IF(G2=H2,"Дост. в срок","Просрочена") -> Просрочена
A3: Авокадо | B3: 280 | C3: 5 | D3: =INT(0.25*C3) -> 1 | E3: =B3*C3 -> 1400 | F3: "Japfruit ComLTD" | G3: 46072 | H3: 46072 | I3: 46075 | J3: =IF(G3=H3,"Дост. в срок","Просрочена") -> Дост. в срок
A4: Баклажан | B4: 120 | C4: 18 | D4: =INT(0.25*C4) -> 4 | E4: =B4*C4 -> 2160 | F4: <<ООО>>"Зарница" | G4: 46070 | H4: 46070 | I4: 46079 | J4: =IF(G4=H4,"Дост. в срок","Просрочена") -> Дост. в срок
A5: Батат | B5: 170 | C5: 10 | D5: =INT(0.25*C5) -> 2 | E5: =B5*C5 -> 1700 | F5: "Japfruit ComLTD" | G5: 46072 | H5: 46072 | I5: 46076 | J5: =IF(G5=H5,"Дост. в срок","Просрочена") -> Дост. в срок
A6: Брокколи | B6: 160 | C6: 10 | D6: =INT(0.25*C6) -> 2 | E6: =B6*C6 -> 1600 | F6: <<ООО>>"Зарница" | G6: 46070 | H6: 46070 | I6: 46072 | J6: =IF(G6=H6,"Дост. в срок","Просрочена") -> Дост. в срок
A7: Брюква | B7: 123 | C7: 16 | D7: =INT(0.25*C7) -> 4 | E7: =B7*C7 -> 1968 | F7: <<ООО>>"Зарница" | G7: 46070 | H7: 46070 | I7: 46073 | J7: =IF(G7=H7,"Дост. в срок","Просрочена") -> Дост. в срок
A8: Горох | B8: 120 | C8: 17 | D8: =INT(0.25*C8) -> 4 | E8: =B8*C8 -> 2040 | F8: <<ООО>>"Зарница" | G8: 46070 | H8: 46070 | I8: 46073 | J8: =IF(G8=H8,"Дост. в срок","Просрочена") -> Дост. в срок
A9: Груши | B9: 120 | C9: 12 | D9: =INT(0.25*C9) -> 3 | E9: =B9*C9 -> 1440 | F9: "ChinaKO TM" | G9: 46073 | H9: 46071 | I9: 46075 | J9: =IF(G9=H9,"Дост. в срок","Просрочена") -> Просрочена
A10: Дайкон | B10: 150 | C10: 12 | D10: =INT(0.25*C10) -> 3 | E10: =B10*C10 -> 1800 | F10: "Japfruit ComLTD" | G10: 46072 | H10: 46072 | I10: 46077 | J10: =IF(G10=H10,"Дост. в срок","Просрочена") -> Дост. в срок
A11: Капуста | B11: 80 | C11: 14 | D11: =INT(0.25*C11) -> 3 | E11: =B11*C11 -> 1120 | F11: <<ООО>>"Зарница" | G11: 46070 | H11: 46070 | I11: 46077 | J11: =IF(G11=H11,"Дост. в срок","Просрочена") -> Дост. в срок
A12: Картофель | B12: 65 | C12: 180 | D12: =INT(0.25*C12) -> 45 | E12: =B12*C12 -> 11700 | F12: <<ООО>>"Зарница" | G12: 46070 | H12: 46070 | I12: 46076 | J12: =IF(G12=H12,"Дост. в срок","Просрочена") -> Дост. в срок
A13: Кольраби | B13: 186 | C13: 5 | D13: =INT(0.25*C13) -> 1 | E13: =B13*C13 -> 930 | F13: "Japfruit ComLTD" | G13: 46072 | H13: 46072 | I13: 46074 | J13: =IF(G13=H13,"Дост. в срок","Просрочена") -> Дост. в срок
... A31: Яблоки | B31: 78 | C31: 40 | D31: =INT(0.25*C31) -> 10 | E31: =B31*C31 -> 3120 | F31: "ChinaKO TM" | G31: 46073 | H31: 46071 | I31: 46078 | J31: =IF(G31=H31,"Дост. в срок","Просрочена") -> Просрочена

Sheet Восток
A1: Продукт | B1: Цена | C1: Кол-во прод в кг | D1: Кол-во ост. | E1: Стоимость | F1: Поставщик | G1: Дата поставки | H1: План. Дата поставки | I1: Дата продажи | J1: Сост. Доставки
A2: Абрикосы | B2: 170 | C2: 20 | D2: =INT(0.25*C2) -> 5 | E2: =B2*C2 -> 3400 | F2: "ChinaKO TM" | G2: 46074 | H2: 46074 | I2: 46076 | J2: =IF(G2=H2,"Дост. в срок","Просрочена") -> Дост. в срок
A3: Авокадо | B3: 250 | C3: 10 | D3: =INT(0.25*C3) -> 2 | E3: =B3*C3 -> 2500 | F3: "Japfruit ComLTD" | G3: 46073 | H3: 46072 | I3: 46076 | J3: =IF(G3=H3,"Дост. в срок","Просрочена") -> Просрочена
A4: Баклажан | B4: 110 | C4: 18 | D4: =INT(0.25*C4) -> 4 | E4: =B4*C4 -> 1980 | F4: <<ООО>>"Зарница" | G4: 46071 | H4: 46071 | I4: 46075 | J4: =IF(G4=H4,"Дост. в срок","Просрочена") -> Дост. в срок
A5: Батат | B5: 142 | C5: 15 | D5: =INT(0.25*C5) -> 3 | E5: =B5*C5 -> 2130 | F5: "Japfruit ComLTD" | G5: 46073 | H5: 46072 | I5: 46076 | J5: =IF(G5=H5,"Дост. в срок","Просрочена") -> Просрочена
A6: Брокколи | B6: 150 | C6: 13 | D6: =INT(0.25*C6) -> 3 | E6: =B6*C6 -> 1950 | F6: <<ООО>>"Зарница" | G6: 46071 | H6: 46071 | I6: 46073 | J6: =IF(G6=H6,"Дост. в срок","Просрочена") -> Дост. в срок
A7: Брюква | B7: 113 | C7: 16 | D7: =INT(0.25*C7) -> 4 | E7: =B7*C7 -> 1808 | F7: <<ООО>>"Зарница" | G7: 46071 | H7: 46071 | I7: 46073 | J7: =IF(G7=H7,"Дост. в срок","Просрочена") -> Дост. в срок
A8: Горох | B8: 102 | C8: 10 | D8: =INT(0.25*C8) -> 2 | E8: =B8*C8 -> 1020 | F8: <<ООО>>"Зарница" | G8: 46071 | H8: 46071 | I8: 46073 | J8: =IF(G8=H8,"Дост. в срок","Просрочена") -> Дост. в срок
A9: Груши | B9: 120 | C9: 12 | D9: =INT(0.25*C9) -> 3 | E9: =B9*C9 -> 1440 | F9: "ChinaKO TM" | G9: 46074 | H9: 46074 | I9: 46075 | J9: =IF(G9=H9,"Дост. в срок","Просрочена") -> Дост. в срок
A10: Дайкон | B10: 130 | C10: 12 | D10: =INT(0.25*C10) -> 3 | E10: =B10*C10 -> 1560 | F10: "Japfruit ComLTD" | G10: 46073 | H10: 46072 | I10: 46076 | J10: =IF(G10=H10,"Дост. в срок","Просрочена") -> Просрочена
A11: Капуста | B11: 76 | C11: 17 | D11: =INT(0.25*C11) -> 4 | E11: =B11*C11 -> 1292 | F11: <<ООО>>"Зарница" | G11: 46071 | H11: 46071 | I11: 46077 | J11: =IF(G11=H11,"Дост. в срок","Просрочена") -> Дост. в срок
A12: Картофель | B12: 56 | C12: 250 | D12: =INT(0.25*C12) -> 62 | E12: =B12*C12 -> 14000 | F12: <<ООО>>"Зарница" | G12: 46071 | H12: 46071 | I12: 46077 | J12: =IF(G12=H12,"Дост. в срок","Просрочена") -> Дост. в срок
A13: Кольраби | B13: 163 | C13: 8 | D13: =INT(0.25*C13) -> 2 | E13: =B13*C13 -> 1304 | F13: "Japfruit ComLTD" | G13: 46073 | H13: 46072 | I13: 46074 | J13: =IF(G13=H13,"Дост. в срок","Просрочена") -> Просрочена
... A31: Яблоки | B31: 78 | C31: 35000 | D31: =INT(0.25*C31) -> 8750 | E31: =B31*C31 -> 2730000 | F31: "ChinaKO TM" | G31: 46074 | H31: 46074 | I31: 46078 | J31: =IF(G31=H31,"Дост. в срок","Просрочена") -> Дост. в срок

Sheet Для сводной
A1: Магазин | B1: Продукт | C1: Цена | D1: Кол-во прод в кг | E1: Кол-во ост. | F1: Стоимость | G1: Поставщик | H1: Дата поставки | I1: План. Дата поставки | J1: Дата продажи | K1: Сост. Доставки | L1: Количество
A2: ="Восток" -> Восток | B2: =Восток!A12 -> Картофель | C2: =Восток!B12 -> 56 | D2: =Восток!C12 -> 250 | E2: =Восток!D12 -> 62 | F2: =Восток!E12 -> 14000 | G2: =Восток!F12 -> <<ООО>>"Зарница" | H2: =Восток!G12 -> 46071 | I2: =Восток!H12 -> 46071 | ... K2: =Восток!J12 -> Дост. в срок | L2: =D2+E2 -> 312 | O2: Значения
A3: ="Восток" -> Восток | B3: =Восток!A16 -> Огурцы | C3: =Восток!B16 -> 79 | D3: =Восток!C16 -> 120 | E3: =Восток!D16 -> 30 | F3: =Восток!E16 -> 9480 | G3: =Восток!F16 -> <<ООО>>"Зарница" | H3: =Восток!G16 -> 46071 | I3: =Восток!H16 -> 46071 | ... K3: =Восток!J16 -> Дост. в срок | L3: =D3+E3 -> 150 | N3: Названия строк | O3: Sum из Стоимость | P3: Среднее из Стоимость | Q3: Макс из Стоимость | R3: Мин из Стоимость
A4: ="Восток" -> Восток | B4: =Восток!A20 -> Помидоры | C4: =Восток!B20 -> 85 | D4: =Восток!C20 -> 100 | E4: =Восток!D20 -> 25 | F4: =Восток!E20 -> 8500 | G4: =Восток!F20 -> <<ООО>>"Зарница" | H4: =Восток!G20 -> 46071 | I4: =Восток!H20 -> 46071 | ... K4: =Восток!J20 -> Дост. в срок | L4: =D4+E4 -> 125 | N4: Восток | O4: 84823 | P4: 84823 | Q4: 84823 | R4: 84823
A5: ="Восток" -> Восток | B5: =Восток!A24 -> Свекла | C5: =Восток!B24 -> 78 | D5: =Восток!C24 -> 54 | E5: =Восток!D24 -> 13 | F5: =Восток!E24 -> 4212 | G5: =Восток!F24 -> <<ООО>>"Зарница" | H5: =Восток!G24 -> 46071 | I5: =Восток!H24 -> 46071 | ... K5: =Восток!J24 -> Дост. в срок | L5: =D5+E5 -> 67 | N5: Запад | O5: 70722 | P5: 70722 | Q5: 70722 | R5: 70722
A6: ="Восток" -> Восток | B6: =Восток!A15 -> Морковь | C6: =Восток!B15 -> 89 | D6: =Восток!C15 -> 40 | E6: =Восток!D15 -> 10 | F6: =Восток!E15 -> 3560 | G6: =Восток!F15 -> <<ООО>>"Зарница" | H6: =Восток!G15 -> 46071 | I6: =Восток!H15 -> 46071 | ... K6: =Восток!J15 -> Дост. в срок | L6: =D6+E6 -> 50 | N6: Север | O6: 433622 | P6: 433622 | Q6: 433622 | R6: 433622
A7: ="Восток" -> Восток | B7: =Восток!A2 -> Абрикосы | C7: =Восток!B2 -> 170 | D7: =Восток!C2 -> 20 | E7: =Восток!D2 -> 5 | F7: =Восток!E2 -> 3400 | G7: =Восток!F2 -> "ChinaKO TM" | H7: =Восток!G2 -> 46074 | I7: =Восток!H2 -> 46074 | ... K7: =Восток!J2 -> Дост. в срок | L7: =D7+E7 -> 25 | N7: Юг | O7: 96516 | P7: 96516 | Q7: 96516 | R7: 96516
A8: ="Восток" -> Восток | B8: =Восток!A28 -> Тыква | C8: =Восток!B28 -> 65 | D8: =Восток!C28 -> 50 | E8: =Восток!D28 -> 12 | F8: =Восток!E28 -> 3250 | G8: =Восток!F28 -> <<ООО>>"Зарница" | H8: =Восток!G28 -> 46071 | I8: =Восток!H28 -> 46071 | ... K8: =Восток!J28 -> Дост. в срок | L8: =D8+E8 -> 62 | N8: Общий итог | O8: 685683 | P8: 685683 | Q8: 685683 | R8: 685683
A9: ="Восток" -> Восток | B9: =Восток!A31 -> Яблоки | C9: =Восток!B31 -> 78 | D9: =Восток!C31 -> 35000 | E9: =Восток!D31 -> 8750 | F9: =Восток!E31 -> 2730000 | G9: =Восток!F31 -> "ChinaKO TM" | H9: =Восток!G31 -> 46074 | I9: =Восток!H31 -> 46074 | ... K9: =Восток!J31 -> Дост. в срок | L9: =D9+E9 -> 43750
A10: ="Восток" -> Восток | B10: =Восток!A3 -> Авокадо | C10: =Восток!B3 -> 250 | D10: =Восток!C3 -> 10 | E10: =Восток!D3 -> 2 | F10: =Восток!E3 -> 2500 | G10: =Восток!F3 -> "Japfruit ComLTD" | H10: =Восток!G3 -> 46073 | I10: =Восток!H3 -> 46072 | ... K10: =Восток!J3 -> Просрочена | L10: =D10+E10 -> 12
A11: ="Восток" -> Восток | B11: =Восток!A17 -> Пастернак | C11: =Восток!B17 -> 125 | D11: =Восток!C17 -> 19 | E11: =Восток!D17 -> 4 | F11: =Восток!E17 -> 2375 | G11: =Восток!F17 -> <<ООО>>"Зарница" | H11: =Восток!G17 -> 46071 | I11: =Восток!H17 -> 46071 | ... K11: =Восток!J17 -> Дост. в срок | L11: =D11+E11 -> 23
A12: ="Восток" -> Восток | B12: =Восток!A29 -> Черешня | C12: =Восток!B29 -> 190 | D12: =Восток!C29 -> 12 | E12: =Восток!D29 -> 3 | F12: =Восток!E29 -> 2280 | G12: =Восток!F29 -> "ChinaKO TM" | H12: =Восток!G29 -> 46074 | I12: =Восток!H29 -> 46074 | ... K12: =Восток!J29 -> Дост. в срок | L12: =D12+E12 -> 15
A13: ="Восток" -> Восток | B13: =Восток!A5 -> Батат | C13: =Восток!B5 -> 142 | D13: =Восток!C5 -> 15 | E13: =Восток!D5 -> 3 | F13: =Восток!E5 -> 2130 | G13: =Восток!F5 -> "Japfruit ComLTD" | H13: =Восток!G5 -> 46073 | I13: =Восток!H5 -> 46072 | ... K13: =Восток!J5 -> Просрочена | L13: =D13+E13 -> 18
A14: ="Восток" -> Восток | B14: =Восток!A4 -> Баклажан | C14: =Восток!B4 -> 110 | D14: =Восток!C4 -> 18 | E14: =Восток!D4 -> 4 | F14: =Восток!E4 -> 1980 | G14: =Восток!F4 -> <<ООО>>"Зарница" | H14: =Восток!G4 -> 46071 | I14: =Восток!H4 -> 46071 | ... K14: =Восток!J4 -> Дост. в срок | L14: =D14+E14 -> 22
A15: ="Восток" -> Восток | B15: =Восток!A6 -> Брокколи | C15: =Восток!B6 -> 150 | D15: =Восток!C6 -> 13 | E15: =Восток!D6 -> 3 | F15: =Восток!E6 -> 1950 | G15: =Восток!F6 -> <<ООО>>"Зарница" | H15: =Восток!G6 -> 46071 | I15: =Восток!H6 -> 46071 | ... K15: =Восток!J6 -> Дост. в срок | L15: =D15+E15 -> 16
A16: ="Восток" -> Восток | B16: =Восток!A14 -> Кукуруза | C16: =Восток!B14 -> 76 | D16: =Восток!C14 -> 25 | E16: =Восток!D14 -> 6 | F16: =Восток!E14 -> 1900 | G16: =Восток!F14 -> <<ООО>>"Зарница" | H16: =Восток!G14 -> 46071 | I16: =Восток!H14 -> 46071 | ... K16: =Восток!J14 -> Дост. в срок | L16: =D16+E16 -> 31
A17: ="Восток" -> Восток | B17: =Восток!A7 -> Брюква | C17: =Восток!B7 -> 113 | D17: =Восток!C7 -> 16 | E17: =Восток!D7 -> 4 | F17: =Восток!E7 -> 1808 | G17: =Восток!F7 -> <<ООО>>"Зарница" | H17: =Восток!G7 -> 46071 | I17: =Восток!H7 -> 46071 | ... K17: =Восток!J7 -> Дост. в срок | L17: =D17+E17 -> 20
A18: ="Восток" -> Восток | B18: =Восток!A19 -> Персики | C18: =Восток!B19 -> 100 | D18: =Восток!C19 -> 18 | E18: =Восток!D19 -> 4 | F18: =Восток!E19 -> 1800 | G18: =Восток!F19 -> "ChinaKO TM" | H18: =Восток!G19 -> 46074 | I18: =Восток!H19 -> 46074 | ... K18: =Восток!J19 -> Дост. в срок | L18: =D18+E18 -> 22
A19: ="Восток" -> Восток | B19: =Восток!A26 -> Спаржа | C19: =Восток!B26 -> 163 | D19: =Восток!C26 -> 11 | E19: =Восток!D26 -> 2 | F19: =Восток!E26 -> 1793 | G19: =Восток!F26 -> "Japfruit ComLTD" | H19: =Восток!G26 -> 46073 | I19: =Восток!H26 -> 46072 | ... K19: =Восток!J26 -> Просрочена | L19: =D19+E19 -> 13
A20: ="Восток" -> Восток | B20: =Восток!A10 -> Дайкон | C20: =Восток!B10 -> 130 | D20: =Восток!C10 -> 12 | E20: =Восток!D10 -> 3 | F20: =Восток!E10 -> 1560 | G20: =Восток!F10 -> "Japfruit ComLTD" | H20: =Восток!G10 -> 46073 | I20: =Восток!H10 -> 46072 | ... K20: =Восток!J10 -> Просрочена | L20: =D20+E20 -> 15
A21: ="Восток" -> Восток | B21: =Восток!A23 -> Репа | C21: =Восток!B23 -> 82 | D21: =Восток!C23 -> 19 | E21: =Восток!D23 -> 4 | F21: =Восток!E23 -> 1558 | G21: =Восток!F23 -> <<ООО>>"Зарница" | H21: =Восток!G23 -> 46071 | I21: =Восток!H23 -> 46071 | ... K21: =Восток!J23 -> Дост. в срок | L21: =D21+E21 -> 23
A22: ="Восток" -> Восток | B22: =Восток!A18 -> Патиссон | C22: =Восток!B18 -> 96 | D22: =Восток!C18 -> 16 | E22: =Восток!D18 -> 4 | F22: =Восток!E18 -> 1536 | G22: =Восток!F18 -> <<ООО>>"Зарница" | H22: =Восток!G18 -> 46071 | I22: =Восток!H18 -> 46071 | ... K22: =Восток!J18 -> Дост. в срок | L22: =D22+E22 -> 20
A23: ="Восток" -> Восток | B23: =Восток!A21 -> Редис | C23: =Восток!B21 -> 95 | D23: =Восток!C21 -> 16 | E23: =Восток!D21 -> 4 | F23: =Восток!E21 -> 1520 | G23: =Восток!F21 -> <<ООО>>"Зарница" | H23: =Восток!G21 -> 46071 | I23: =Восток!H21 -> 46071 | ... K23: =Восток!J21 -> Дост. в срок | L23: =D23+E23 -> 20
A24: ="Восток" -> Восток | B24: =Восток!A9 -> Груши | C24: =Восток!B9 -> 120 | D24: =Восток!C9 -> 12 | E24: =Восток!D9 -> 3 | F24: =Восток!E9 -> 1440 | G24: =Восток!F9 -> "ChinaKO TM" | H24: =Восток!G9 -> 46074 | I24: =Восток!H9 -> 46074 | ... K24: =Восток!J9 -> Дост. в срок | L24: =D24+E24 -> 15
A25: ="Восток" -> Восток | B25: =Восток!A27 -> Топинамбур | C25: =Восток!B27 -> 105 | D25: =Восток!C27 -> 13 | E25: =Восток!D27 -> 3 | F25: =Восток!E27 -> 1365 | G25: =Восток!F27 -> "Japfruit ComLTD" | H25: =Восток!G27 -> 46073 | I25: =Восток!H27 -> 46072 | ... K25: =Восток!J27 -> Просрочена | L25: =D25+E25 -> 16
A26: ="Восток" -> Восток | B26: =Восток!A13 -> Кольраби | C26: =Восток!B13 -> 163 | D26: =Восток!C13 -> 8 | E26: =Восток!D13 -> 2 | F26: =Восток!E13 -> 1304 | G26: =Восток!F13 -> "Japfruit ComLTD" | H26: =Восток!G13 -> 46073 | I26: =Восток!H13 -> 46072 | ... K26: =Восток!J13 -> Просрочена | L26: =D26+E26 -> 10
A27: ="Восток" -> Восток | B27: =Восток!A11 -> Капуста | C27: =Восток!B11 -> 76 | D27: =Восток!C11 -> 17 | E27: =Восток!D11 -> 4 | F27: =Восток!E11 -> 1292 | G27: =Восток!F11 -> <<ООО>>"Зарница" | H27: =Восток!G11 -> 46071 | I27: =Восток!H11 -> 46071 | ... K27: =Восток!J11 -> Дост. в срок | L27: =D27+E27 -> 21
A28: ="Восток" -> Восток | B28: =Восток!A30 -> Чеснок | C28: =Восток!B30 -> 42 | D28: =Восток!C30 -> 30 | E28: =Восток!D30 -> 7 | F28: =Восток!E30 -> 1260 | G28: =Восток!F30 -> <<ООО>>"Зарница" | H28: =Восток!G30 -> 46071 | I28: =Восток!H30 -> 46071 | ... K28: =Восток!J30 -> Дост. в срок | L28: =D28+E28 -> 37
A29: ="Восток" -> Восток | B29: =Восток!A22 -> Редька | C29: =Восток!B22 -> 90 | D29: =Восток!C22 -> 12 | E29: =Восток!D22 -> 3 | F29: =Восток!E22 -> 1080 | G29: =Восток!F22 -> <<ООО>>"Зарница" | H29: =Восток!G22 -> 46071 | I29: =Восток!H22 -> 46071 | ... K29: =Восток!J22 -> Дост. в срок | L29: =D29+E29 -> 15
A30: ="Восток" -> Восток | B30: =Восток!A8 -> Горох | C30: =Восток!B8 -> 102 | D30: =Восток!C8 -> 10 | E30: =Восток!D8 -> 2 | F30: =Восток!E8 -> 1020 | G30: =Восток!F8 -> <<ООО>>"Зарница" | H30: =Восток!G8 -> 46071 | I30: =Восток!H8 -> 46071 | ... K30: =Восток!J8 -> Дост. в срок | L30: =D30+E30 -> 12
A31: ="Восток" -> Восток | B31: =Восток!A25 -> Сельдерей | C31: =Восток!B25 -> 120 | D31: =Восток!C25 -> 2 | E31: =Восток!D25 -> 0 | F31: =Восток!E25 -> 240 | G31: =Восток!F25 -> "Japfruit ComLTD" | H31: =Восток!G25 -> 46073 | I31: =Восток!H25 -> 46072 | ... K31: =Восток!J25 -> Просрочена | L31: =D31+E31 -> 2
A32: ="Запад" -> Запад | B32: =Запад!A12 -> Картофель | C32: =Запад!B12 -> 65 | D32: =Запад!C12 -> 180 | E32: =Запад!D12 -> 45 | F32: =Запад!E12 -> 11700 | G32: =Запад!F12 -> <<ООО>>"Зарница" | H32: =Запад!G12 -> 46070 | I32: =Запад!H12 -> 46070 | ... K32: =Запад!J12 -> Дост. в срок | L32: =D32+E32 -> 225
A33: ="Запад" -> Запад | B33: =Запад!A20 -> Помидоры | C33: =Запад!B20 -> 110 | D33: =Запад!C20 -> 50 | E33: =Запад!D20 -> 12 | F33: =Запад!E20 -> 5500 | G33: =Запад!F20 -> <<ООО>>"Зарница" | H33: =Запад!G20 -> 46070 | I33: =Запад!H20 -> 46070 | ... K33: =Запад!J20 -> Дост. в срок | L33: =D33+E33 -> 62
A34: ="Запад" -> Запад | B34: =Запад!A16 -> Огурцы | C34: =Запад!B16 -> 90 | D34: =Запад!C16 -> 60 | E34: =Запад!D16 -> 15 | F34: =Запад!E16 -> 5400 | G34: =Запад!F16 -> <<ООО>>"Зарница" | H34: =Запад!G16 -> 46070 | I34: =Запад!H16 -> 46070 | ... K34: =Запад!J16 -> Дост. в срок | L34: =D34+E34 -> 75
A35: ="Запад" -> Запад | B35: =Запад!A2 -> Абрикосы | C35: =Запад!B2 -> 180 | D35: =Запад!C2 -> 20 | E35: =Запад!D2 -> 5 | F35: =Запад!E2 -> 3600 | G35: =Запад!F2 -> "ChinaKO TM" | H35: =Запад!G2 -> 46073 | I35: =Запад!H2 -> 46071 | ... K35: =Запад!J2 -> Просрочена | L35: =D35+E35 -> 25
A36: ="Запад" -> Запад | B36: =Запад!A31 -> Яблоки | C36: =Запад!B31 -> 78 | D36: =Запад!C31 -> 40 | E36: =Запад!D31 -> 10 | F36: =Запад!E31 -> 3120 | G36: =Запад!F31 -> "ChinaKO TM" | H36: =Запад!G31 -> 46073 | I36: =Запад!H31 -> 46071 | ... K36: =Запад!J31 -> Просрочена | L36: =D36+E36 -> 50
A37: ="Запад" -> Запад | B37: =Запад!A15 -> Морковь | C37: =Запад!B15 -> 100 | D37: =Запад!C15 -> 30 | E37: =Запад!D15 -> 7 | F37: =Запад!E15 -> 3000 | G37: =Запад!F15 -> <<ООО>>"Зарница" | H37: =Запад!G15 -> 46070 | I37: =Запад!H15 -> 46070 | ... K37: =Запад!J15 -> Дост. в срок | L37: =D37+E37 -> 37
A38: ="Запад" -> Запад | B38: =Запад!A29 -> Черешня | C38: =Запад!B29 -> 220 | D38: =Запад!C29 -> 12 | E38: =Запад!D29 -> 3 | F38: =Запад!E29 -> 2640 | G38: =Запад!F29 -> "ChinaKO TM" | H38: =Запад!G29 -> 46073 | I38: =Запад!H29 -> 46071 | ... K38: =Запад!J29 -> Просрочена | L38: =D38+E38 -> 15
A39: ="Запад" -> Запад | B39: =Запад!A17 -> Пастернак | C39: =Запад!B17 -> 125 | D39: =Запад!C17 -> 20 | E39: =Запад!D17 -> 5 | F39: =Запад!E17 -> 2500 | G39: =Запад!F17 -> <<ООО>>"Зарница" | H39: =Запад!G17 -> 46070 | I39: =Запад!H17 -> 46070 | ... K39: =Запад!J17 -> Дост. в срок | L39: =D39+E39 -> 25
A40: ="Запад" -> Запад | B40: =Запад!A24 -> Свекла | C40: =Запад!B24 -> 78 | D40: =Запад!C24 -> 30 | E40: =Запад!D24 -> 7 | F40: =Запад!E24 -> 2340 | G40: =Запад!F24 -> <<ООО>>"Зарница" | H40: =Запад!G24 -> 46070 | I40: =Запад!H24 -> 46070 | ... K40: =Запад!J24 -> Дост. в срок | L40: =D40+E40 -> 37
...

Sheet Поставщики
A1: Названия строк | B1: Sum из Количество
A2: "ChinaKO TM" | B2: 886
A3: "Japfruit ComLTD" | B3: 356
A4: <<ООО>>"Зарница" | B4: 3785
A5: Общий итог | B5: 5027

Sheet Яблоки
A1: Продукт | B1: Яблоки
A3: Названия строк | B3: Сумма из Кол-во прод в кг
A4: Восток | B4: 35000
A5: Запад | B5: 40
A6: Север | B6: 350
A7: Юг | B7: 35
A8: Общий итог | B8: 35425
